[2021-01-21 23:22:54,215] {taskinstance.py:826} INFO - Dependencies all met for <TaskInstance: trigger_rule.task_1 2021-01-21T23:22:53.765633+00:00 [queued]>
[2021-01-21 23:22:54,233] {taskinstance.py:826} INFO - Dependencies all met for <TaskInstance: trigger_rule.task_1 2021-01-21T23:22:53.765633+00:00 [queued]>
[2021-01-21 23:22:54,233] {taskinstance.py:1017} INFO - 
--------------------------------------------------------------------------------
[2021-01-21 23:22:54,234] {taskinstance.py:1018} INFO - Starting attempt 1 of 1
[2021-01-21 23:22:54,234] {taskinstance.py:1019} INFO - 
--------------------------------------------------------------------------------
[2021-01-21 23:22:54,243] {taskinstance.py:1038} INFO - Executing <Task(BashOperator): task_1> on 2021-01-21T23:22:53.765633+00:00
[2021-01-21 23:22:54,245] {standard_task_runner.py:51} INFO - Started process 594360 to run task
[2021-01-21 23:22:54,252] {standard_task_runner.py:75} INFO - Running: ['airflow', 'tasks', 'run', 'trigger_rule', 'task_1', '2021-01-21T23:22:53.765633+00:00', '--job-id', '106', '--pool', 'default_pool', '--raw', '--subdir', 'DAGS_FOLDER/trigger_rule.py', '--cfg-path', '/tmp/tmprxyqg_3o']
[2021-01-21 23:22:54,253] {standard_task_runner.py:76} INFO - Job 106: Subtask task_1
[2021-01-21 23:22:54,302] {logging_mixin.py:103} INFO - Running <TaskInstance: trigger_rule.task_1 2021-01-21T23:22:53.765633+00:00 [running]> on host ip-172-31-18-6.ap-south-1.compute.internal
[2021-01-21 23:22:54,351] {taskinstance.py:1232} INFO - Exporting the following env vars:
AIRFLOW_CTX_DAG_OWNER=airflow
AIRFLOW_CTX_DAG_ID=trigger_rule
AIRFLOW_CTX_TASK_ID=task_1
AIRFLOW_CTX_EXECUTION_DATE=2021-01-21T23:22:53.765633+00:00
AIRFLOW_CTX_DAG_RUN_ID=manual__2021-01-21T23:22:53.765633+00:00
[2021-01-21 23:22:54,351] {bash.py:135} INFO - Tmp dir root location: 
 /tmp
[2021-01-21 23:22:54,352] {bash.py:158} INFO - Running command: exit 1
[2021-01-21 23:22:54,359] {bash.py:169} INFO - Output:
[2021-01-21 23:22:54,360] {bash.py:177} INFO - Command exited with return code 1
[2021-01-21 23:22:54,373] {taskinstance.py:1396} ERROR - Bash command failed. The command returned a non-zero exit code.
Traceback (most recent call last):
  File "/home/ubuntu/anaconda3/envs/airflow_udemy/lib/python3.7/site-packages/airflow/models/taskinstance.py", line 1086, in _run_raw_task
    self._prepare_and_execute_task_with_callbacks(context, task)
  File "/home/ubuntu/anaconda3/envs/airflow_udemy/lib/python3.7/site-packages/airflow/models/taskinstance.py", line 1260, in _prepare_and_execute_task_with_callbacks
    result = self._execute_task(context, task_copy)
  File "/home/ubuntu/anaconda3/envs/airflow_udemy/lib/python3.7/site-packages/airflow/models/taskinstance.py", line 1300, in _execute_task
    result = task_copy.execute(context=context)
  File "/home/ubuntu/anaconda3/envs/airflow_udemy/lib/python3.7/site-packages/airflow/operators/bash.py", line 180, in execute
    raise AirflowException('Bash command failed. The command returned a non-zero exit code.')
airflow.exceptions.AirflowException: Bash command failed. The command returned a non-zero exit code.
[2021-01-21 23:22:54,375] {taskinstance.py:1440} INFO - Marking task as FAILED. dag_id=trigger_rule, task_id=task_1, execution_date=20210121T232253, start_date=20210121T232254, end_date=20210121T232254
[2021-01-21 23:22:54,421] {local_task_job.py:118} INFO - Task exited with return code 1
