[2021-01-21 22:05:25,496] {taskinstance.py:826} INFO - Dependencies all met for <TaskInstance: user_processing.creating_table 2021-01-12T00:00:00+00:00 [queued]>
[2021-01-21 22:05:25,533] {taskinstance.py:826} INFO - Dependencies all met for <TaskInstance: user_processing.creating_table 2021-01-12T00:00:00+00:00 [queued]>
[2021-01-21 22:05:25,534] {taskinstance.py:1017} INFO - 
--------------------------------------------------------------------------------
[2021-01-21 22:05:25,534] {taskinstance.py:1018} INFO - Starting attempt 1 of 1
[2021-01-21 22:05:25,534] {taskinstance.py:1019} INFO - 
--------------------------------------------------------------------------------
[2021-01-21 22:05:25,545] {taskinstance.py:1038} INFO - Executing <Task(SqliteOperator): creating_table> on 2021-01-12T00:00:00+00:00
[2021-01-21 22:05:25,557] {standard_task_runner.py:51} INFO - Started process 36936 to run task
[2021-01-21 22:05:25,567] {standard_task_runner.py:75} INFO - Running: ['airflow', 'tasks', 'run', 'user_processing', 'creating_table', '2021-01-12T00:00:00+00:00', '--job-id', '15', '--pool', 'default_pool', '--raw', '--subdir', 'DAGS_FOLDER/user_processing.py', '--cfg-path', '/tmp/tmpp1chr439']
[2021-01-21 22:05:25,578] {standard_task_runner.py:76} INFO - Job 15: Subtask creating_table
[2021-01-21 22:05:25,684] {logging_mixin.py:103} INFO - Running <TaskInstance: user_processing.creating_table 2021-01-12T00:00:00+00:00 [running]> on host ip-172-31-18-6.ap-south-1.compute.internal
[2021-01-21 22:05:25,754] {taskinstance.py:1232} INFO - Exporting the following env vars:
AIRFLOW_CTX_DAG_OWNER=airflow
AIRFLOW_CTX_DAG_ID=user_processing
AIRFLOW_CTX_TASK_ID=creating_table
AIRFLOW_CTX_EXECUTION_DATE=2021-01-12T00:00:00+00:00
AIRFLOW_CTX_DAG_RUN_ID=scheduled__2021-01-12T00:00:00+00:00
[2021-01-21 22:05:25,754] {sqlite.py:57} INFO - Executing: 
            CREATE TABLE IF NOT EXISTS users (
                firstname TEXT NOT NULL,
                lastname TEXT NOT NULL,
                country TEXT NOT NULL,
                username TEXT NOT NULL,
                password TEXT NOT NULL,
                email TEXT NOT NULL PRIMARY KEY
            );
        
[2021-01-21 22:05:25,787] {taskinstance.py:1396} ERROR - The conn_id `db_sqlite` isn't defined
Traceback (most recent call last):
  File "/home/ubuntu/anaconda3/envs/airflow_udemy/lib/python3.7/site-packages/airflow/models/taskinstance.py", line 1086, in _run_raw_task
    self._prepare_and_execute_task_with_callbacks(context, task)
  File "/home/ubuntu/anaconda3/envs/airflow_udemy/lib/python3.7/site-packages/airflow/models/taskinstance.py", line 1260, in _prepare_and_execute_task_with_callbacks
    result = self._execute_task(context, task_copy)
  File "/home/ubuntu/anaconda3/envs/airflow_udemy/lib/python3.7/site-packages/airflow/models/taskinstance.py", line 1300, in _execute_task
    result = task_copy.execute(context=context)
  File "/home/ubuntu/anaconda3/envs/airflow_udemy/lib/python3.7/site-packages/airflow/providers/sqlite/operators/sqlite.py", line 59, in execute
    hook.run(self.sql, parameters=self.parameters)
  File "/home/ubuntu/anaconda3/envs/airflow_udemy/lib/python3.7/site-packages/airflow/hooks/dbapi.py", line 173, in run
    with closing(self.get_conn()) as conn:
  File "/home/ubuntu/anaconda3/envs/airflow_udemy/lib/python3.7/site-packages/airflow/providers/sqlite/hooks/sqlite.py", line 35, in get_conn
    airflow_conn = self.get_connection(conn_id)
  File "/home/ubuntu/anaconda3/envs/airflow_udemy/lib/python3.7/site-packages/airflow/hooks/base.py", line 63, in get_connection
    conn = Connection.get_connection_from_secrets(conn_id)
  File "/home/ubuntu/anaconda3/envs/airflow_udemy/lib/python3.7/site-packages/airflow/models/connection.py", line 354, in get_connection_from_secrets
    raise AirflowNotFoundException(f"The conn_id `{conn_id}` isn't defined")
airflow.exceptions.AirflowNotFoundException: The conn_id `db_sqlite` isn't defined
[2021-01-21 22:05:25,788] {taskinstance.py:1440} INFO - Marking task as FAILED. dag_id=user_processing, task_id=creating_table, execution_date=20210112T000000, start_date=20210121T220525, end_date=20210121T220525
[2021-01-21 22:05:25,823] {local_task_job.py:118} INFO - Task exited with return code 1
