[2021-01-21 22:39:34,156] {taskinstance.py:826} INFO - Dependencies all met for <TaskInstance: xcom_dag.processing_tasks.training_model_c 2021-01-21T22:39:29.621997+00:00 [queued]>
[2021-01-21 22:39:34,180] {taskinstance.py:826} INFO - Dependencies all met for <TaskInstance: xcom_dag.processing_tasks.training_model_c 2021-01-21T22:39:29.621997+00:00 [queued]>
[2021-01-21 22:39:34,181] {taskinstance.py:1017} INFO - 
--------------------------------------------------------------------------------
[2021-01-21 22:39:34,181] {taskinstance.py:1018} INFO - Starting attempt 1 of 1
[2021-01-21 22:39:34,181] {taskinstance.py:1019} INFO - 
--------------------------------------------------------------------------------
[2021-01-21 22:39:34,193] {taskinstance.py:1038} INFO - Executing <Task(PythonOperator): processing_tasks.training_model_c> on 2021-01-21T22:39:29.621997+00:00
[2021-01-21 22:39:34,200] {standard_task_runner.py:51} INFO - Started process 285614 to run task
[2021-01-21 22:39:34,206] {standard_task_runner.py:75} INFO - Running: ['airflow', 'tasks', 'run', 'xcom_dag', 'processing_tasks.training_model_c', '2021-01-21T22:39:29.621997+00:00', '--job-id', '43', '--pool', 'default_pool', '--raw', '--subdir', 'DAGS_FOLDER/xcom_dag.py', '--cfg-path', '/tmp/tmpdafgeemu']
[2021-01-21 22:39:34,206] {standard_task_runner.py:76} INFO - Job 43: Subtask processing_tasks.training_model_c
[2021-01-21 22:39:34,268] {logging_mixin.py:103} INFO - Running <TaskInstance: xcom_dag.processing_tasks.training_model_c 2021-01-21T22:39:29.621997+00:00 [running]> on host ip-172-31-18-6.ap-south-1.compute.internal
[2021-01-21 22:39:34,318] {taskinstance.py:1232} INFO - Exporting the following env vars:
AIRFLOW_CTX_DAG_OWNER=airflow
AIRFLOW_CTX_DAG_ID=xcom_dag
AIRFLOW_CTX_TASK_ID=processing_tasks.training_model_c
AIRFLOW_CTX_EXECUTION_DATE=2021-01-21T22:39:29.621997+00:00
AIRFLOW_CTX_DAG_RUN_ID=manual__2021-01-21T22:39:29.621997+00:00
[2021-01-21 22:39:34,319] {logging_mixin.py:103} INFO - model's accuracy: 4.76194769440268
[2021-01-21 22:39:34,319] {taskinstance.py:1396} ERROR - xcom_pull() got an unexpected keyword argument 'value'
Traceback (most recent call last):
  File "/home/ubuntu/anaconda3/envs/airflow_udemy/lib/python3.7/site-packages/airflow/models/taskinstance.py", line 1086, in _run_raw_task
    self._prepare_and_execute_task_with_callbacks(context, task)
  File "/home/ubuntu/anaconda3/envs/airflow_udemy/lib/python3.7/site-packages/airflow/models/taskinstance.py", line 1260, in _prepare_and_execute_task_with_callbacks
    result = self._execute_task(context, task_copy)
  File "/home/ubuntu/anaconda3/envs/airflow_udemy/lib/python3.7/site-packages/airflow/models/taskinstance.py", line 1300, in _execute_task
    result = task_copy.execute(context=context)
  File "/home/ubuntu/anaconda3/envs/airflow_udemy/lib/python3.7/site-packages/airflow/operators/python.py", line 117, in execute
    return_value = self.execute_callable()
  File "/home/ubuntu/anaconda3/envs/airflow_udemy/lib/python3.7/site-packages/airflow/operators/python.py", line 128, in execute_callable
    return self.python_callable(*self.op_args, **self.op_kwargs)
  File "/home/ubuntu/airflow/dags/xcom_dag.py", line 18, in _training_model
    task_instance.xcom_pull(key='model_accuracy',value=accuracy)
  File "/home/ubuntu/anaconda3/envs/airflow_udemy/lib/python3.7/site-packages/airflow/utils/session.py", line 65, in wrapper
    return func(*args, session=session, **kwargs)
TypeError: xcom_pull() got an unexpected keyword argument 'value'
[2021-01-21 22:39:34,324] {taskinstance.py:1440} INFO - Marking task as FAILED. dag_id=xcom_dag, task_id=processing_tasks.training_model_c, execution_date=20210121T223929, start_date=20210121T223934, end_date=20210121T223934
[2021-01-21 22:39:34,375] {local_task_job.py:118} INFO - Task exited with return code 1
